INFO     log:logger_util.py:61 
-------------接口请求开始-----------
INFO     log:logger_util.py:61 接口名称：在运行版搜索配方
INFO     log:logger_util.py:61 接口方式：get
INFO     log:logger_util.py:61 接口路径：http://127.0.0.1:18000/api/v1/runtimeformula/name/get-all?formulaSetId=c6405838-d772-4417-ab66-f00f014b5c60&filter=配方
INFO     log:logger_util.py:61 请求头：{'X-Project': 'bbc7f11ea34c42649ea1404008bcc83a', 'Authorization': 'Bearer eyJhbGciOiJIUzI1NiIsInR5cCI6IkpXVCJ9.eyJodHRwOi8vc2NoZW1hcy54bWxzb2FwLm9yZy93cy8yMDA1LzA1L2lkZW50aXR5L2NsYWltcy9uYW1lIjoiU3VwZXJBZG1pbiIsImh0dHA6Ly9zY2hlbWFzLnhtbHNvYXAub3JnL3dzLzIwMDUvMDUvaWRlbnRpdHkvY2xhaW1zL25hbWVpZGVudGlmaWVyIjoiU3VwZXJBZG1pbiIsImlzcyI6IkNNU3YyIiwiYXVkIjoiQXBpIn0.AJUOE6YQ5MAxDqHOIz-yQbpCKPNq5tPoFBWUY381qns'}
INFO     log:logger_util.py:61 文件上传：None
INFO     log:logger_util.py:65 断言失败:status_code不等于200
INFO     log:logger_util.py:61 实际结果：{'code': 409, 'msg': 'Projcet Conflict'}
INFO     log:logger_util.py:61 接口请求失败！
INFO     log:logger_util.py:61 -------------接口请求结束-----------

INFO     log:logger_util.py:65 断言异常：异常信息: Traceback (most recent call last):
  File "D:\CMS2.0_API\EOS_API_AUTOMATION_TEST\common\requests_util.py", line 369, in validate_result
    error_log("断言失败:"+assert_key+"不等于"+str(assert_value))
  File "D:\CMS2.0_API\EOS_API_AUTOMATION_TEST\common\logger_util.py", line 66, in error_log
    raise Exception(log_message)
Exception: 断言失败:status_code不等于200

INFO     log:logger_util.py:65 分析YAML文件异常：异常信息: Traceback (most recent call last):
  File "D:\CMS2.0_API\EOS_API_AUTOMATION_TEST\common\requests_util.py", line 369, in validate_result
    error_log("断言失败:"+assert_key+"不等于"+str(assert_value))
  File "D:\CMS2.0_API\EOS_API_AUTOMATION_TEST\common\logger_util.py", line 66, in error_log
    raise Exception(log_message)
Exception: 断言失败:status_code不等于200

During handling of the above exception, another exception occurred:

Traceback (most recent call last):
  File "D:\CMS2.0_API\EOS_API_AUTOMATION_TEST\common\requests_util.py", line 248, in analysis_yaml
    self.validate_result(yq_result, return_data, status_code)
  File "D:\CMS2.0_API\EOS_API_AUTOMATION_TEST\common\requests_util.py", line 481, in validate_result
    error_log("断言异常：异常信息: %s" % str(traceback.format_exc()))
  File "D:\CMS2.0_API\EOS_API_AUTOMATION_TEST\common\logger_util.py", line 66, in error_log
    raise Exception(log_message)
Exception: 断言异常：异常信息: Traceback (most recent call last):
  File "D:\CMS2.0_API\EOS_API_AUTOMATION_TEST\common\requests_util.py", line 369, in validate_result
    error_log("断言失败:"+assert_key+"不等于"+str(assert_value))
  File "D:\CMS2.0_API\EOS_API_AUTOMATION_TEST\common\logger_util.py", line 66, in error_log
    raise Exception(log_message)
Exception: 断言失败:status_code不等于200