INFO     log:logger_util.py:61 
-------------接口请求开始-----------
INFO     log:logger_util.py:61 接口名称：移动工程节点
INFO     log:logger_util.py:61 接口方式：put
INFO     log:logger_util.py:61 接口路径：http://127.0.0.1:18000/api/v1/project/node/moveprojectnodes
INFO     log:logger_util.py:61 请求头：{}
INFO     log:logger_util.py:61 请求参数：{'destNodeID': '14', 'selectNodeIDs': "{'code': 500, 'exception': {'callStack': [{'assembly': 'System.Private.CoreLib', 'fileName': 'C:\\GitLab-Runner\\builds\\uF5yEnPSn\\0\\cms\\cms\\src\\Plugins\\CMS.Plugin.Project\\Services\\ProjectManagerService.cs', 'lineNumber': 436, 'method': 'MoveNext'}, {'assembly': 'System.Private.CoreLib', 'fileName': 'C:\\GitLab-Runner\\builds\\uF5yEnPSn\\0\\cms\\cms\\src\\Plugins\\CMS.Plugin.Project\\Services\\ProjectManagerService.cs', 'lineNumber': 87, 'method': 'MoveNext'}, {'assembly': 'System.Private.CoreLib', 'fileName': 'C:\\GitLab-Runner\\builds\\uF5yEnPSn\\0\\cms\\cms\\src\\Plugins\\CMS.Plugin.Project\\Controllers\\V1\\NodeController.cs', 'lineNumber': 46, 'method': 'MoveNext'}, {'assembly': 'System.Private.CoreLib', 'fileName': 'C:\\GitLab-Runner\\builds\\uF5yEnPSn\\0\\cms\\cms\\src\\Framework\\CMS.Framework.Authorization.AspNetCore\\Middlewares\\AuthorizationMiddleware.cs', 'lineNumber': 47, 'method': 'MoveNext'}, {'assembly': 'System.Private.CoreLib', 'fileName': 'C:\\GitLab-Runner\\builds\\uF5yEnPSn\\0\\cms\\cms\\src\\CMS.Core\\TraceMiddleware.cs', 'lineNumber': 21, 'method': 'MoveNext'}, {'assembly': 'System.Private.CoreLib', 'fileName': 'C:\\GitLab-Runner\\builds\\uF5yEnPSn\\0\\cms\\cms\\src\\Framework\\CMS.Framework.AspNetCore\\Middlewares\\ExceptionMonitorMiddleware.cs', 'lineNumber': 36, 'method': 'MoveNext'}], 'innerException': None, 'message': '存储路径下已存在重名工程，请重新输入', 'type': 'Exception', 'when': '2024-07-24T11:45:50.825747+08:00'}, 'msg': '存储路径下已存在重名工程，请重新输入'}"}
INFO     log:logger_util.py:61 文件上传：None
INFO     log:logger_util.py:65 断言失败:status_code不等于200
INFO     log:logger_util.py:61 实际结果：{'exception': None, 'code': 400, 'msg': "The value '{'code': 500, 'exception': {'callStack': [{'assembly': 'System.Private.CoreLib', 'fileName': 'C:\\GitLab-Runner\\builds\\uF5yEnPSn\\0\\cms\\cms\\src\\Plugins\\CMS.Plugin.Project\\Services\\ProjectManagerService.cs', 'lineNumber': 436, 'method': 'MoveNext'}, {'assembly': 'System.Private.CoreLib', 'fileName': 'C:\\GitLab-Runner\\builds\\uF5yEnPSn\\0\\cms\\cms\\src\\Plugins\\CMS.Plugin.Project\\Services\\ProjectManagerService.cs', 'lineNumber': 87, 'method': 'MoveNext'}, {'assembly': 'System.Private.CoreLib', 'fileName': 'C:\\GitLab-Runner\\builds\\uF5yEnPSn\\0\\cms\\cms\\src\\Plugins\\CMS.Plugin.Project\\Controllers\\V1\\NodeController.cs', 'lineNumber': 46, 'method': 'MoveNext'}, {'assembly': 'System.Private.CoreLib', 'fileName': 'C:\\GitLab-Runner\\builds\\uF5yEnPSn\\0\\cms\\cms\\src\\Framework\\CMS.Framework.Authorization.AspNetCore\\Middlewares\\AuthorizationMiddleware.cs', 'lineNumber': 47, 'method': 'MoveNext'}, {'assembly': 'System.Private.CoreLib', 'fileName': 'C:\\GitLab-Runner\\builds\\uF5yEnPSn\\0\\cms\\cms\\src\\CMS.Core\\TraceMiddleware.cs', 'lineNumber': 21, 'method': 'MoveNext'}, {'assembly': 'System.Private.CoreLib', 'fileName': 'C:\\GitLab-Runner\\builds\\uF5yEnPSn\\0\\cms\\cms\\src\\Framework\\CMS.Framework.AspNetCore\\Middlewares\\ExceptionMonitorMiddleware.cs', 'lineNumber': 36, 'method': 'MoveNext'}], 'innerException': None, 'message': '存储路径下已存在重名工程，请重新输入', 'type': 'Exception', 'when': '2024-07-24T11:45:50.825747+08:00'}, 'msg': '存储路径下已存在重名工程，请重新输入'}' is not valid."}
INFO     log:logger_util.py:61 接口请求失败！
INFO     log:logger_util.py:61 -------------接口请求结束-----------

INFO     log:logger_util.py:65 断言异常：异常信息: Traceback (most recent call last):
  File "D:\CMS2.0_API\EOS_API_AUTOMATION_TEST\common\requests_util.py", line 369, in validate_result
    error_log("断言失败:"+assert_key+"不等于"+str(assert_value))
  File "D:\CMS2.0_API\EOS_API_AUTOMATION_TEST\common\logger_util.py", line 66, in error_log
    raise Exception(log_message)
Exception: 断言失败:status_code不等于200

INFO     log:logger_util.py:65 分析YAML文件异常：异常信息: Traceback (most recent call last):
  File "D:\CMS2.0_API\EOS_API_AUTOMATION_TEST\common\requests_util.py", line 369, in validate_result
    error_log("断言失败:"+assert_key+"不等于"+str(assert_value))
  File "D:\CMS2.0_API\EOS_API_AUTOMATION_TEST\common\logger_util.py", line 66, in error_log
    raise Exception(log_message)
Exception: 断言失败:status_code不等于200

During handling of the above exception, another exception occurred:

Traceback (most recent call last):
  File "D:\CMS2.0_API\EOS_API_AUTOMATION_TEST\common\requests_util.py", line 248, in analysis_yaml
    self.validate_result(yq_result, return_data, status_code)
  File "D:\CMS2.0_API\EOS_API_AUTOMATION_TEST\common\requests_util.py", line 481, in validate_result
    error_log("断言异常：异常信息: %s" % str(traceback.format_exc()))
  File "D:\CMS2.0_API\EOS_API_AUTOMATION_TEST\common\logger_util.py", line 66, in error_log
    raise Exception(log_message)
Exception: 断言异常：异常信息: Traceback (most recent call last):
  File "D:\CMS2.0_API\EOS_API_AUTOMATION_TEST\common\requests_util.py", line 369, in validate_result
    error_log("断言失败:"+assert_key+"不等于"+str(assert_value))
  File "D:\CMS2.0_API\EOS_API_AUTOMATION_TEST\common\logger_util.py", line 66, in error_log
    raise Exception(log_message)
Exception: 断言失败:status_code不等于200